{"uuid": "7b370d68-87e2-4386-bf64-6135dd5f7786", "children": ["86de00fe-7af7-4ddf-8eb6-8ccce0629a65"], "befores": [{"name": "setup", "status": "broken", "statusDetails": {"message": "selenium.common.exceptions.WebDriverException: Message: unknown error: Chrome failed to start: exited normally.\n  (chrome not reachable)\n  (The process started from chrome location C:\\Program Files\\Google\\Chrome\\Application\\chrome.exe is no longer running, so ChromeDriver is assuming that Chrome has crashed.)\nStacktrace:\nBacktrace:\n\tGetHandleVerifier [0x0098A813+48355]\n\t(No symbol) [0x0091C4B1]\n\t(No symbol) [0x00825358]\n\t(No symbol) [0x00843621]\n\t(No symbol) [0x00840579]\n\t(No symbol) [0x00870C55]\n\t(No symbol) [0x0087093C]\n\t(No symbol) [0x0086A536]\n\t(No symbol) [0x008482DC]\n\t(No symbol) [0x008493DD]\n\tGetHandleVerifier [0x00BEAABD+2539405]\n\tGetHandleVerifier [0x00C2A78F+2800735]\n\tGetHandleVerifier [0x00C2456C+2775612]\n\tGetHandleVerifier [0x00A151E0+616112]\n\t(No symbol) [0x00925F8C]\n\t(No symbol) [0x00922328]\n\t(No symbol) [0x0092240B]\n\t(No symbol) [0x00914FF7]\n\tBaseThreadInitThunk [0x766E7D59+25]\n\tRtlInitializeExceptionChain [0x7715B79B+107]\n\tRtlClearBits [0x7715B71F+191]\n\n", "trace": "  File \"C:\\Users\\makde\\AppData\\Local\\Programs\\Python\\Python311\\Lib\\site-packages\\pluggy\\_callers.py\", line 80, in _multicall\n    res = hook_impl.function(*args)\n          ^^^^^^^^^^^^^^^^^^^^^^^^^\n  File \"C:\\Users\\makde\\AppData\\Local\\Programs\\Python\\Python311\\Lib\\site-packages\\_pytest\\fixtures.py\", line 1123, in pytest_fixture_setup\n    result = call_fixture_func(fixturefunc, request, kwargs)\n             ^^^^^^^^^^^^^^^^^^^^^^^^^^^^^^^^^^^^^^^^^^^^^^^\n  File \"C:\\Users\\makde\\AppData\\Local\\Programs\\Python\\Python311\\Lib\\site-packages\\_pytest\\fixtures.py\", line 902, in call_fixture_func\n    fixture_result = fixturefunc(**kwargs)\n                     ^^^^^^^^^^^^^^^^^^^^^\n  File \"C:\\Users\\makde\\Desktop\\SW Testing\\Pytest framework\\CredKart_pytest_project 31-07-2023\\CredKart_Pytest_Project - Copy\\testCases\\conftest.py\", line 37, in setup\n    driver = webdriver.Chrome()\n             ^^^^^^^^^^^^^^^^^^\n  File \"C:\\Users\\makde\\AppData\\Local\\Programs\\Python\\Python311\\Lib\\site-packages\\selenium\\webdriver\\chrome\\webdriver.py\", line 49, in __init__\n    super().__init__(\n  File \"C:\\Users\\makde\\AppData\\Local\\Programs\\Python\\Python311\\Lib\\site-packages\\selenium\\webdriver\\chromium\\webdriver.py\", line 54, in __init__\n    super().__init__(\n  File \"C:\\Users\\makde\\AppData\\Local\\Programs\\Python\\Python311\\Lib\\site-packages\\selenium\\webdriver\\remote\\webdriver.py\", line 206, in __init__\n    self.start_session(capabilities)\n  File \"C:\\Users\\makde\\AppData\\Local\\Programs\\Python\\Python311\\Lib\\site-packages\\selenium\\webdriver\\remote\\webdriver.py\", line 291, in start_session\n    response = self.execute(Command.NEW_SESSION, caps)[\"value\"]\n               ^^^^^^^^^^^^^^^^^^^^^^^^^^^^^^^^^^^^^^^\n  File \"C:\\Users\\makde\\AppData\\Local\\Programs\\Python\\Python311\\Lib\\site-packages\\selenium\\webdriver\\remote\\webdriver.py\", line 346, in execute\n    self.error_handler.check_response(response)\n  File \"C:\\Users\\makde\\AppData\\Local\\Programs\\Python\\Python311\\Lib\\site-packages\\selenium\\webdriver\\remote\\errorhandler.py\", line 245, in check_response\n    raise exception_class(message, screen, stacktrace)\n"}, "start": 1691475665637, "stop": 1691475673384}], "start": 1691475665637, "stop": 1691475673514}